Workbook

Sheet ATUALIZA AUTOMAT.
A1: CENSO DE DIETA DA UTI | P1: HORÁRIO: | Q1: =NOW() -> 46009.434
A2: LEITO | B2: NOME | F2: IDADE | G2: DIETA | I2: OBSERVAÇÃO | N2: META | O2: ÁGUA | P2: PESO | Q2: DI.UTI | R2: PRONT.
A3: LEITO 01 | B3: {=SORT('L1'!D1:G1)} -> EDITE SOARES DA SILVA | F3: {=SORT('L1'!I1)} -> 73 | G3: {=SORT('L1'!L29:M29)} -> DIBEN | I3: {=SORT('L1'!N31:Q34)} -> OBS: 56 ML/H + SUPLEMENTAÇÃO, RESTRIÇAO HIDRICA POR BALANÇO MUITO POSITIVO | N3: {=SORT('L1'!O30)} -> 56 ML/H | O3: {=SORT('L1'!Q30)} -> RH | P3: {=SORT('L1'!Q29)} -> 65.4 | Q3: {=SORT('L1'!D2)} -> 45992.021 | R3: {=SORT('L1'!B1)} -> 64111
A7: LEITO 02 | B7: {=SORT('L2'!D1:G1)} -> ZILDA DE OLIVEIRA ZOCATELLI | F7: {=SORT('L2'!I1)} -> 76 | G7: {=SORT('L2'!L29:M29)} -> JEJUM | I7: {=SORT('L2'!N31:Q34)} -> OBS: SNE | N7: {=SORT('L2'!O30)} -> 58ML/H | O7: {=SORT('L2'!Q30)} -> RH | P7: {=SORT('L2'!Q29)} -> 97.2 | Q7: {=SORT('L2'!D2)} -> 46001.917 | R7: {=SORT('L2'!B1)} -> 359245
A11: LEITO 03 | B11: {=SORT('L3'!D1:G1)} -> VERA LUCIA BARBOSA | F11: {=SORT('L3'!I1)} -> 63 | G11: {=SORT('L3'!L29:M29)} -> JEJUM | I11: {=SORT('L3'!N31:Q34)} -> OBS: | N11: {=SORT('L3'!O30)} | O11: {=SORT('L3'!Q30)} -> 800 DIA | P11: {=SORT('L3'!Q29)} -> 70 | Q11: {=SORT('L3'!D2)} -> 46008 | R11: {=SORT('L3'!B1)} -> 202183
A15: LEITO 04 | B15: {=SORT('L4'!D1:G1)} -> LUIZ FERNANDO SIRQUEIRA | F15: {=SORT('L4'!I1)} -> 47 | G15: {=SORT('L4'!L29:M29)} -> JEJUM | I15: {=SORT('L4'!N31:Q34)} -> ALMOÇO/JANTAR: SOPA COADA | N15: {=SORT('L4'!O30)} -> LIQUIDA | O15: {=SORT('L4'!Q30)} -> RH | P15: {=SORT('L4'!Q29)} -> 80 | Q15: {=SORT('L4'!D2)} -> 46005 | R15: {=SORT('L4'!B1)} -> 578852
A19: LEITO 05
A23: LEITO 06 | B23: {=SORT('L6'!D1:G1)} | F23: {=SORT('L6'!I1)} | G23: {=SORT('L6'!L29:M29)} | N23: {=SORT('L6'!O30)} | O23: {=SORT('L6'!Q30)} | P23: {=SORT('L6'!Q29)} | R23: {=SORT('L6'!B1)}
A27: LEITO 07 | B27: APARECIDO TOLEDO | F27: 76 | G27: LEVE/ HAS /DM | O27: 1500 | Q27: 46008 | R27: 211305
A31: LEITO 08 | B31: {=SORT('L8'!D1:G1)} -> ELIZABETI GONÇALVES BRAGA | F31: {=SORT('L8'!I1)} -> 61 | G31: {=SORT('L8'!L29:M29)} -> DIBEN | I31: {=SORT('L8'!N31:Q34)} -> OBS: LIBERADO DIETA. SUPLEMENTAÇÃO HIPERPROTEICA | N31: {=SORT('L8'!O30)} -> 75 ML/H | O31: {=SORT('L8'!Q30)} -> RH | P31: {=SORT('L8'!Q29)} -> 131 | Q31: {=SORT('L8'!D2)} -> 46000.542 | R31: {=SORT('L8'!B1)} -> 577523
A35: LEITO 09 | B35: {=SORT('L9'!D1:G1)} -> ANTONIO CARLOS CASSIMIRA | F35: {=SORT('L9'!I1)} -> 58 | G35: {=SORT('L9'!L29:M29)} -> HP ENERGI | I35: {=SORT('L9'!N31:Q34)} -> OBS: 1,73 ALTURA | N35: {=SORT('L9'!O30)} -> 55ML/H | O35: {=SORT('L9'!Q30)} -> RH | P35: {=SORT('L9'!Q29)} -> 81.7 | Q35: {=SORT('L9'!D2)} -> 16/12 AS | R35: {=SORT('L9'!B1)} -> 579000
A39: ISOLAM. | B39: {=SORT('L10'!D1:G1)} -> VANESSA APARECIDA RODRIGUES DOS SANTOS | F39: {=SORT('L10'!I1)} -> 36 | G39: {=SORT('L10'!L29:M29)} -> JEJUM | I39: {=SORT('L10'!N31:Q34)} -> OBS: 1,62 ALTURA | N39: {=SORT('L10'!O30)} -> *** | O39: {=SORT('L10'!Q30)} -> RH | P39: {=SORT('L10'!Q29)} -> 60 | Q39: {=SORT('L10'!D2)} -> 46007 | R39: {=SORT('L10'!B1)} -> 46032

Sheet L1
A1: FA | B1: 64111 | C1: PACIENTE | D1: EDITE SOARES DA SILVA | H1: IDADE | I1: 73 | J1: ALERGIAS (anotar quando tiver) | L1: HD: | M1: 1- RNC >> IOT (25/11) - 2- DESCARTADO >> MENINGOENCEFALITE VIRAL 3- MASSA CERVICAL ANTERIOR >> NEOPLASIA DE TIREOIDE A/E 4- HEPATITE A ESCLARECER>> HEPATITE ISQUÊMICA? >>INFECCIOSA? | R1: LEITO
A2: DIH | B2: 45988 | C2: D.UTI | D2: 45992.021 | E2: PREV. ALTA | F2: 14 | G2: QNTOS DIAS: | H2: =(D2+F2)-O2 -> 46006.021 | R2: 1
A3: HDA | B3: PACIENTE ADMITIDA POR RNC, SUSPEITA DE MENINGITE COM LIQUOR NEGATIVO, MASA CERVICAL ANTERIOR E MEDIASTINO / ANTECEDENTE DE PARKINSON, MANTEM NEUROLOGICO ALTERADO , EVOLUI COM PAV DURANTE INTERNAÇAO. | R3: DATA
A4: HPP | B4: DOENÇA DE PARKINSON , NEO TIREÓIDE | R4: =TODAY() -> 46009
A5: MUC | B5: DULOXETINA, MIRTAZPINA, PROLOPA, MARTIDAN
A6: SUBJETIVO | C6: OBJETIVO | K6: ANALISE POR SISTEMA | R6: PLANO DO DIA
A7: QX: PACIENTE, FAMILIAR, EQUIPE ASSISTENCIAL | C7: EXAME FÍSICO ALTERADO: | K7: 1) NEURO
C8: DESORIENTADA, GEMENTE HIPERSECRETIVA, RONCUS ESPARSOS | K8: SEDOANALGESIA | L8: VAZÃO | M8: INICIO | N8: FIM | O8: GLASGOW | P8: 11 | R8: AGURDA RESONANCIA//TENTAR ALTA PARA ESTIMULO FAMILIAR
A9: GEMENTE | K9: PRECEDEX 2X | L9: 0 | M9: 45972 | N9: 46006 | O9: RASS:
O10: Pupilas: | P10: PIRF
O11: DESPERTAR DIARIO/RASS<-2 | P11: NA
O12: - Rodizio de sedação? | P12: NA
O13: Avaliação dor/analgesia | P13: SIM
A14: IMPRESSÃO GERAL | C14: CONTROLES DE ENFERMAGEM | F14: HEMODIALISE | I14: BALANÇO HIDRICO: | K14: 3) CARDIOVASCULAR
A15: (Das ultimas 24 h) | C15: CONTROLE DE (h) | E15: 24 | F15: DATA | G15: TEMPO | H15: PERDAS | I15: DIURESE: | J15: 778 | K15: DVAs | L15: VAZÃO | M15: INICIO | N15: FIM | O15: PAM / MMNHG | P15: 78 | R15: INICIO VASOPRESSINA E DESMAME PROGRSSIVO DE NORA
A16: BEG | B16: FALSE | D16: MIN | E16: MAX | K16: NORADRENALINA 4X | L16: 2 | M16: 46004 | O16: FC | P16: 77
A17: REG | B17: TRUE | C17: PAM: | D17: 56 | E17: 106 | I17: HMD: | J17: -- | K17: VASOPRESSINA 2X | L17: 6 | M17: 46009 | O17: TEC | P17: 2
A18: MEG | B18: FALSE | C18: FC | D18: 71 | E18: 96 | O18: ESTAVEL HMD | P18: NÃO
A19: EVOLUÇÃO | C19: FR | D19: 13 | E19: 19 | I19: BH: | J19: -528 | O19: REDUZIR DVAs | P19: SIM
A20: FAVORÁVEL | B20: FALSE | C20: TEMP | D20: 35 | E20: 35.8 | F20: DRENOS | O20: ALTERAÇÕES ECG | P20: NÃO
A21: ESTACIONÁRIA | B21: TRUE | C21: SAT | D21: 92 | E21: 99 | F21: SNE | H21: 100 | I21: ULTIMA EVACUAÇÃO (DATA) | K21: 2) RESPIRATÓRIO
A22: DESFAVORÁVEL | B22: FALSE | C22: DEXTRO | D22: 54 | E22: 238 | I22: 46005 | K22: Ventilação: | L22: AA | M22: MODO | O22: RIMA | Q22: MANHA: | R22: NOITE: ASP VAS MEDIA QNTD ASPECTO DE DIETA ENTERAL // RX CONTROLE DE SNE
A23: POR QUÊ ? | K23: Protocolo de Desmame: | M23: FR | N23: 16 | O23: Relação I:E
A24: MANTEM GEMENCIA , DESORIENTADA, DVAS DEPENDIENTE | C24: LABORATORIAIS ALTERADOS | F24: CULTURAS / SOROLOGIAS | K24: Data de prona: | M24: FIO2 | O24: Ppico | Q24: TARDE:
D25: ONTEM | E25: HOJE | F25: DATA | G25: TIPO | H25: RESULTADO | K25: Pcuff Manha | M25: PEEP | O25: Pplatô | Q25: ASP VAS
C26: Hemoglobina | D26: 8 | E26: 8 | F26: 45996 | G26: ST | H26: PSEUDOMONAS MULTI R. | K26: Pcuff Tarde | M26: PC/VC/PS | O26: IRRS/Tobin | Q26: NOITE:
C27: Hematocrito | K27: Pcuff Noite | M27: Fluxo | O27: DP | Q27: ASP VAS
C28: Leucocitos | D28: 14 | E28: 14 | K28: 4) ABDOMINAL /NUTRI
A29: ESCALAS | C29: plaquetas | K29: DIETA | L29: DIBEN | N29: VIA | O29: SNE | P29: PESO: | Q29: 65.4 | R29: APRIMORAR PROCINETICOS/ CLISTER PRÉ BANHO
A30: BRADEN | B30: 06 A 09 | C30: PCR | E30: 39 | K30: VAZÃO ATUAL: | L30: 50ML | M30: VAZÃO META: | O30: 56 ML/H | P30: ÁGUA: | Q30: RH
A31: MORSE | B31: > 51 | C31: Uréia | D31: 90 | E31: 75 | K31: Atingidiu meta 2000 kcal? | L31: SIM | N31: OBS: 56 ML/H + SUPLEMENTAÇÃO, RESTRIÇAO HIDRICA POR BALANÇO MUITO POSITIVO
A32: FUGULIN | B32: 21 - 26 | C32: Creatinina | K32: Glicemia(alvo80-180mg/dl)? | L32: NÃO
A33: PPS | B33: 90 | C33: Sódio | K33: Evacuação normal? | L33: NÃO
A34: SAPS3 | B34: 78 | C34: Potássio | D34: 3 | E34: 2.6 | K34: Profilaxia úlceras gástricas? | L34: SIM
A35: TX.MORT% | B35: 83 | C35: Calcio | D35: 7.44 | F35: EXAMES DE IMAGENS | K35: 5) RENAL / GENITOURINARIO
A36: DIGNO DE NOTA | C36: Magnésio | D36: 1.49 | F36: DATA | G36: TIPO | H36: RESULTADO | K36: Balanço hídrico neutro: | L36: NÃO | N36: OBS: | R36: SUSPENSO DIURÉTICO, CORREÇÃO DE POTASSIO
A37: 17/12; ASPIRAÇAO DE VIAS AEREAS COM ASPECTO DE DIETA ,SUSPENSO DIETA E ABERTO SNE PÓREM SEM DEBITO | C37: Albumina | F37: 46000 | G37: USG | H37: MICROLITIASE VESICULA BILIAR | K37: Reposição eletrolítica? | L37: SIM
C38: Troponina | K38: Diurese > 0,5 ml / Kg/H? | L38: =(J15/Q29)/E15 -> 0.49566769
C39: CPK | K39: Plano Dialítico | L39: NÃO
C40: CKMB | K40: Inicio de Dialise
...

Sheet L2
A1: FA | B1: 359245 | C1: PACIENTE | D1: ZILDA DE OLIVEIRA ZOCATELLI | H1: IDADE | I1: 76 | J1: ALERGIAS (anotar quando tiver) | L1: HD: | M1: 1. IC DESCOMPENSADA PERFIL B - 2. FEBRE MACULOSA? 3. PNEUMONIA - 4. FARMACODERMIA? -5. HIPONATREMIA 6. HDB 7.CHOQUE MISTO | R1: LEITO
A2: DIH | B2: 45989 | C2: D.UTI | D2: 46001.917 | E2: PREV. ALTA | F2: 7 | G2: QNTOS DIAS: | R2: 2
A3: HDA | B3: PACIENTE DA ENTRADA NO PS PELO SAMU, COM QUEIXAS DE EDEMAS EM MMII, DISPNEIA, TOSSE, FILHA RELATA QUE A MESMA TEVE CONTATO COM CARRAPATOS HA 20 DIAS | R3: DATA
A4: HPP | B4: HAS | R4: =TODAY() -> 46009
A5: MUC | B5: LOSARTANA 50 MG
A6: SUBJETIVO | C6: OBJETIVO | K6: ANALISE POR SISTEMA | R6: PLANO DO DIA
A7: QX: PACIENTE, FAMILIAR, EQUIPE ASSISTENCIAL | C7: EXAME FÍSICO ALTERADO: | K7: 1) NEURO
C8: PALIDA DESORIENTADA, ABDOME DOLOROSO A PALPAÇAO DIFUSA COM DEFENSA PERITOENAL / MAL DISTRUBUIDA TEMPO DE ENCHIMENTO CAPILAR < 3SEG, DEPENDIENTE DE OXIGENIO , HIPOTENSA, RONCUS ABUNDANTES EM AUSCULTA PULMONAR | K8: SEDOANALGESIA | L8: VAZÃO | M8: INICIO | N8: FIM | O8: GLASGOW | P8: 3
A9: ALGICA , DOR ABDOMINAL IMPORTANTE | K9: MIDAZOLAM 2X | L9: 5 | M9: 46008 | O9: RASS: | P9: -5
K10: FENTANIL | L10: 1 | M10: 46008 | O10: Pupilas: | P10: PIRF
O11: DESPERTAR DIARIO/RASS<-2 | P11: SIM
O12: - Rodizio de sedação? | P12: NÃO
O13: Avaliação dor/analgesia | P13: SIM
A14: IMPRESSÃO GERAL | C14: CONTROLES DE ENFERMAGEM | F14: HEMODIALISE | I14: BALANÇO HIDRICO: | K14: 3) CARDIOVASCULAR
A15: (Das ultimas 24 h) | C15: CONTROLE DE (h) | E15: 24 | F15: DATA | G15: TEMPO | H15: PERDAS | I15: DIURESE: | J15: 75 | K15: DVAs | L15: VAZÃO | M15: INICIO | N15: FIM | O15: PAM / MMNHG | P15: 80 | R15: ASOCIAR VASOPRESSINA , HIDROCORTISONA DOSE CHOQUE
A16: BEG | B16: FALSE | D16: MIN | E16: MAX | K16: NORADRENALINA 4X | L16: 26 | M16: 46008 | O16: FC | P16: 77
A17: REG | B17: TRUE | C17: PAM | D17: 64 | E17: 112 | I17: HMD: | K17: VASOPRESSINA 2X | L17: 6 | M17: 46008 | O17: TEC | P17: 4
A18: MEG | B18: FALSE | C18: FC | D18: 74 | E18: 121 | K18: DOBUTAMINA 4X | L18: - | M18: 46002 | N18: 46003 | O18: ESTAVEL HMD | P18: NÃO
A19: EVOLUÇÃO | C19: FR | D19: 18 | E19: 21 | I19: BH: | J19: 2.074(+) | O19: REDUZIR DVAs | P19: NÃO
A20: FAVORÁVEL | B20: FALSE | C20: TEMP | D20: 36.6 | E20: 37.8 | F20: DRENOS | O20: ALTERAÇÕES ECG | P20: SIM
A21: ESTACIONÁRIA | B21: FALSE | C21: SAT | D21: 94 | E21: 97 | I21: ULTIMA EVACUAÇÃO (DATA) | K21: 2) RESPIRATÓRIO
A22: DESFAVORÁVEL | B22: TRUE | C22: DEXTRO | D22: 169 | E22: 180 | I22: 46008 | K22: Ventilação: | L22: TOT | M22: MODO | N22: VCV | O22: RIMA | P22: 24 | Q22: MANHÃ | R22: TC SUSPENSA POR INSTABILIDADE
A23: POR QUÊ ? | K23: Protocolo de Desmame: | M23: FR | N23: 18 | O23: Relação I:E
A24: RETIRADA DVAS, TOLEROU DIETA VO, SEM HEMORRGIA ATIVA | C24: LABORATORIAIS ALTERADOS | F24: CULTURAS / SOROLOGIAS | K24: Data de prona: | M24: FIO2 | N24: 35 | O24: Ppico | P24: 19 | Q24: TARDE:
D25: ONTEM | E25: HOJE | F25: DATA | G25: TIPO | H25: RESULTADO | K25: Pcuff Manha | M25: PEEP | N25: 6 | O25: Pplatô | P25: 17 | Q25: RNC - IOT
C26: Hemoglobina | D26: 8.9 | E26: 9 | F26: 46002 | G26: SWAB | H26: ACINETO | K26: Pcuff Tarde | M26: PC/VC/PS | N26: 390 | O26: IRRS/Tobin | Q26: NOITE:
C27: Hematocrito | D27: 29 | E27: 27 | F27: 46001 | G27: HEMO/URO | K27: Pcuff Noite | L27: 30 | M27: Fluxo | O27: DP | Q27: Secretiva
C28: Leucocitos | D28: 11 | E28: 19 | F28: 46004 | G28: HEMO/URO | K28: 4) ABDOMINAL /NUTRI
A29: ESCALAS | C29: plaquetas | F29: 46008 | G29: HEMO | K29: DIETA | L29: JEJUM | N29: VIA | O29: SNE | P29: PESO: | Q29: 97.2 | R29: MANTER JEJUM POR INSTABILIDADE
A30: BRADEN | B30: 10 - 12 | C30: PCR | D30: 62 | E30: 40 | K30: VAZÃO ATUAL: | L30: 0 | M30: VAZÃO META: | O30: 58ML/H | P30: ÁGUA: | Q30: RH
A31: MORSE | B31: 41 - 51 | C31: Uréia | D31: 52 | E31: 72 | K31: Atingidiu meta 2000 kcal? | L31: NÃO | N31: OBS: SNE
A32: FUGULIN | B32: >31 | C32: Creatinina | K32: Glicemia(alvo80-180mg/dl)? | L32: NÃO
A33: PPS | B33: 90 | C33: Sódio | D33: 163 | E33: 162 | K33: Evacuação normal? | L33: SIM
A34: SAPS3 | B34: 54 | C34: Potássio | D34: 2.4 | K34: Profilaxia úlceras gástricas? | L34: SIM
A35: TX.MORT% | B35: 33.1 | C35: Calcio | D35: 1.3 | F35: EXAMES DE IMAGENS | K35: 5) RENAL / GENITOURINARIO
A36: DIGNO DE NOTA | C36: Magnésio | F36: DATA | G36: TIPO | H36: RESULTADO | K36: Balanço hídrico neutro: | L36: NÃO | N36: OBS: | R36: INICIAR HCTZ , RESTRINGIR CLORETOS/ MANTER PAM >90
A37: 16/12- SACADO CVD, MANTIDO CVC, SEM CONDIÇÃO PERIFERICO // PACIENTE COM RNC, EVOLUI PARA TOT, PROCEDIMENTO SEM INTERCORRENCIAS./ PENDENTE TOMO DE TÓRAX, URINA 1 E UROCULTURA, MANTÉM DIETA SUSPEMSA DEVIDO A INSTABILIDADE, SUPENSO TOMOGRAFIA DE TÓRAX DEVIDO A INSTABILIDADE HEMODINAMICA. | C37: Albumina | F37: 46001 | G37: TC CRN | H37: https://mobilemed-prod.s3.amazonaws.com/producao/exame/laudo_signed/1765419598282-I96ry~3E2Iu3kvxcL018uiE5~fsYJY.pdf | K37: Reposição eletrolítica? | L37: SIM
C38: Troponina | F38: 46001 | G38: TC ABD / PELVE | H38: https://mobilemed-prod.s3.amazonaws.com/producao/exame/laudo_signed/1765419327316-DMHFElGQ6WLaGnoo8Gz7Zn0spXETZ4.pdf | K38: Diurese > 0,5 ml / Kg/H? | L38: =(J15/Q29)/E15 -> 0.032150206
C39: CPK | F39: 46003 | G39: EDA | H39: EROSAO PLANA BULBAR (FORREST III) | K39: Plano Dialítico | L39: NÃO
C40: CKMB | F40: 46005 | G40: ECO | H40: FE;54%/ACINECIA SEPTO INF, APICAL | K40: Inicio de Dialise
...

Sheet L3
A1: FA | B1: 202183 | C1: PACIENTE | D1: VERA LUCIA BARBOSA | H1: IDADE | I1: 63 | J1: ALERGIAS (anotar quando tiver) | K1: PENICILINA | L1: HD: | M1: AVCH | R1: LEITO
A2: DIH | B2: 46008 | C2: D.UTI | D2: 46008 | E2: PREV. ALTA | G2: QNTOS DIAS: | R2: 3
A3: HDA | B3: PACIENTE ENCAMINHADA DA UPA, RECEBIDA PELA MANHA DE HOJE, POR OUTRO PLANTONISTA COM A SEGUINTE HISTORIA: PACIENTE TRAZIDA À UNIDADE - UPA - PELO FILHO COM RELATO DE A MESMA TER INICIADO QUADRO SÚBITO DE NÁUSEAS, VÔMITOS, SONOLÊNCIA E REBAIXAMENTO DO NÍVEL DE CONSCIÊNCIA SÚBITO. INÍCIO POR VOLTA DAS 22H. ATÉ ENTÃO, ENCONTRAVA SE EM SEU ESTADO BASAL. DÁ ENTRADA SONOLENTA, APRESENTANDO VÔMITOS ESCURECIDOS EM GRANDE QUANTIDADE - SEM REAÇÃO COM Á GUA OXIGENADA. PCT. APRESENTA PIORA DO QUADRO GERAL (NEUROLÓGICO, CLINICO E RESPIRATORIO) COM REDUÇÃO DO GLASGOW ABAIXO DE 08 SENDO NECESSARIO REALIZAÇÃO DE IOT SOB SEDAÇÃO + SEDAÇÃO CONTINUA. | R3: DATA
A4: HPP | B4: HAS | R4: =TODAY() -> 46009
A5: MUC
A6: SUBJETIVO | C6: OBJETIVO | K6: ANALISE POR SISTEMA | R6: PLANO DO DIA
A7: QX: PACIENTE, FAMILIAR, EQUIPE ASSISTENCIAL | C7: EXAME FÍSICO ALTERADO: | K7: 1) NEURO
K8: SEDOANALGESIA | L8: VAZÃO | M8: INICIO | N8: FIM | O8: GLASGOW | P8: 3 | R8: CROSS PARA NEUROCG
K9: MIDAZOLAM 2X | L9: 2 | M9: 46008 | O9: RASS: | P9: -5
K10: FENTANIL | L10: 7 | M10: 46008 | O10: Pupilas: | P10: PINFR
O11: DESPERTAR DIARIO/RASS<-2 | P11: NÃO
O12: - Rodizio de sedação? | P12: NÃO
O13: Avaliação dor/analgesia | P13: SIM
A14: IMPRESSÃO GERAL | C14: CONTROLES DE ENFERMAGEM | F14: HEMODIALISE | I14: BALANÇO HIDRICO: | K14: 3) CARDIOVASCULAR
A15: (Das ultimas 24 h) | C15: CONTROLE DE (h) | E15: 24 | F15: DATA | G15: TEMPO | H15: PERDAS | I15: DIURESE: | J15: 220 | K15: DVAs | L15: VAZÃO | M15: INICIO | N15: FIM | O15: PAM / MMNHG | P15: 69
A16: BEG | B16: FALSE | D16: MIN | E16: MAX | O16: FC | P16: 90
A17: REG | B17: FALSE | C17: PAM: | I17: HMD: | O17: TEC | P17: 3
A18: MEG | B18: TRUE | C18: FC | O18: ESTAVEL HMD | P18: SIM
A19: EVOLUÇÃO | C19: FR | I19: BH: | J19: -51 | O19: REDUZIR DVAs | P19: N/A
A20: FAVORÁVEL | B20: FALSE | C20: TEMP | F20: DRENOS | O20: ALTERAÇÕES ECG | P20: NÃO
A21: ESTACIONÁRIA | B21: FALSE | C21: SAT | I21: ULTIMA EVACUAÇÃO (DATA) | K21: 2) RESPIRATÓRIO
A22: DESFAVORÁVEL | B22: TRUE | C22: DEXTRO | K22: Ventilação: | L22: TOT | M22: MODO | N22: PCV | O22: RIMA | P22: 19 | Q22: MANHA: | R22: PENDENTE GASOMETRIA E RX DE TRX
A23: POR QUÊ ? | C23: 70 | K23: Protocolo de Desmame: | M23: FR | N23: 20 | O23: T.I | P23: 1
C24: LABORATORIAIS ALTERADOS | F24: CULTURAS / SOROLOGIAS | K24: Data de prona: | M24: FIO2 | N24: 0.4 | O24: Ppico | P24: 19 | Q24: TARDE:
D25: ONTEM | E25: HOJE | F25: DATA | G25: TIPO | H25: RESULTADO | K25: Pcuff Manha | M25: PEEP | N25: 6 | O25: Pplatô | P25: 10 | Q25: ADMISSAO
C26: Hemoglobina | F26: 46008 | G26: HEMO | K26: Pcuff Tarde | M26: PC/VC/PS | N26: 12 | O26: IRRS/Tobin | Q26: NOITE:
C27: Hematocrito | F27: 46008 | G27: URO | K27: Pcuff Noite | L27: 30 | M27: Fluxo | O27: DP | Q27: HES
C28: Leucocitos | F28: 46008 | G28: SWAB | K28: 4) ABDOMINAL /NUTRI
A29: ESCALAS | C29: plaquetas | K29: DIETA | L29: JEJUM | N29: VIA | O29: SNE | P29: PESO: | Q29: 70
A30: BRADEN | B30: 13 A 14 | C30: PCR | K30: VAZÃO ATUAL: | M30: VAZÃO META: | P30: ÁGUA: | Q30: 800 DIA
A31: MORSE | B31: >51 | C31: Uréia | K31: Atingidiu meta 2000 kcal? | L31: SIM | N31: OBS:
A32: FUGULIN | B32: 27 A 31 | C32: Creatinina | K32: Glicemia(alvo80-180mg/dl)? | L32: NÃO
A33: PPS | C33: Sódio | K33: Evacuação normal? | L33: NÃO
A34: SAPS3 | C34: Potássio | K34: Profilaxia úlceras gástricas? | L34: SIM
A35: TX.MORT% | C35: Calcio | F35: EXAMES DE IMAGENS | K35: 5) RENAL / GENITOURINARIO
A36: DIGNO DE NOTA | C36: Magnésio | F36: DATA | G36: TIPO | H36: RESULTADO | K36: Balanço hídrico neutro: | L36: SIM | N36: OBS:
A37: PACIENTE TRANSFERIDA PARA O HES AS 00:15HS 18/12/25,PARA AVLIAÇÃO DA NRC, NÃO CONSEGUI ENTRAR EM CONTATO COM FAMILIARES PARA AVISAR DA TRANSFERENCIA,REALIZADO VARIAS TENTATIVAS SEM SUCESSO. | C37: Albumina | F37: 46008 | G37: RX | K37: Reposição eletrolítica? | L37: NÃO
C38: Troponina | F38: 46008 | G38: TC CRN | H38: https://mobilemed-prod.s3.amazonaws.com/producao/exame/laudo_signed/1766004662832-N16od8fodkH060kveySOmEG1VBAkoZ.pdf | K38: Diurese > 0,5 ml / Kg/H? | L38: =(J15/Q29)/E15 -> 0.13095238
C39: CPK | F39: 46008 | G39: TC TRX | H39: https://mobilemed-prod.s3.amazonaws.com/producao/exame/laudo_signed/1766004664586-x9Fke_qV3WmR5SPGvvPlRjPp1CnO4a.pdf | K39: Plano Dialítico | L39: NÃO
C40: CKMB | K40: Inicio de Dialise
...

Sheet L4
A1: FA | B1: 578852 | C1: PACIENTE | D1: LUIZ FERNANDO SIRQUEIRA | H1: IDADE | I1: 47 | J1: ALERGIAS (anotar quando tiver) | K1: NEGA | L1: HD: | M1: LE (14/12) LISE DE BRIDAS + DRENAGEM DE ABSCESSO DE FERIDA OPERATÓRIA / PO3 (11/12) APENDICECTOMIA | R1: LEITO
A2: DIH | B2: 46005 | C2: D.UTI | D2: 46005 | E2: PREV. ALTA | G2: QNTOS DIAS: | R2: 4
A3: HDA | B3: PACIENTE COMPARECE NA UNIDADE COM RELATO DE INAPETÊNCIA, NÁUSEAS, VOMITOS, DOR ABDOMINAL DIFUSA HÁ 3 DIAS APÓS APENDICECTOMIA. NEGA FEBRE. AFIRMA CONSTIPAÇÃO INTESTINAL. NEGA DEMAIS QUEIXAS E SINTOMAS. | R3: DATA
A4: HPP | B4: TBG, ETILISMO E UDI, HERNIA DE DISCO | R4: 46006
A5: MUC
A6: SUBJETIVO | C6: OBJETIVO | K6: ANALISE POR SISTEMA | R6: PLANO DO DIA
A7: QX: PACIENTE, FAMILIAR, EQUIPE ASSISTENCIAL | C7: EXAME FÍSICO ALTERADO: | K7: 1) NEURO
C8: ANSIOSO, DISTENSAO ABDOMINAL APOS DIETA, ELIMINAÇAO FLATOS , EVACUO 1 VEZ | K8: SEDOANALGESIA | L8: VAZÃO | M8: INICIO | N8: FIM | O8: GLASGOW | P8: 15 | R8: APRIMORAR ANALGESIA EVITAR OPIOIDES
A9: ANSIOSO, DOR EM REGIAO COLUMNA | O9: RASS:
O10: Pupilas: | P10: PIRF
O11: DESPERTAR DIARIO/RASS<-2 | P11: N/A
O12: - Rodizio de sedação? | P12: N/A
O13: Avaliação dor/analgesia | P13: SIM
A14: IMPRESSÃO GERAL | C14: CONTROLES DE ENFERMAGEM | F14: HEMODIALISE | I14: BALANÇO HIDRICO: | K14: 3) CARDIOVASCULAR
A15: (Das ultimas 24 h) | C15: CONTROLE DE (h) | E15: 24 | F15: DATA | G15: TEMPO | H15: PERDAS | I15: DIURESE: | J15: 500 | K15: DVAs | L15: VAZÃO | M15: INICIO | N15: FIM | O15: PAM / MMNHG | P15: 92
A16: BEG | B16: FALSE | D16: MIN | E16: MAX | O16: FC | P16: 87
A17: REG | B17: TRUE | C17: PAM | D17: 82 | E17: 98 | I17: HMD: | J17: - | O17: TEC | P17: 3
A18: MEG | B18: FALSE | C18: FC | D18: 66 | E18: 84 | O18: ESTAVEL HMD | P18: SIM
A19: EVOLUÇÃO | C19: FR | D19: 16 | E19: 20 | I19: BH: | J19: 71(-) | O19: REDUZIR DVAs | P19: N/A
A20: FAVORÁVEL | B20: TRUE | C20: TEMP | D20: 36 | E20: 37.2 | F20: DRENOS | O20: ALTERAÇÕES ECG | P20: NÃO
A21: ESTACIONÁRIA | B21: FALSE | C21: SAT | D21: 94 | E21: 96 | F21: SNG | H21: 450 | I21: ULTIMA EVACUAÇÃO (DATA) | K21: 2) RESPIRATÓRIO
A22: DESFAVORÁVEL | B22: FALSE | C22: DEXTRO | D22: 101 | E22: 119 | F22: PENROSE | H22: 0 | I22: 17/12/2025 (+) | K22: Ventilação: | L22: AA | M22: MODO | O22: RIMA | Q22: MANHA: | R22: FISIOTERAPIA MOTORA , TOLERA DEAMBULAÇAO E BANHO CHUVEIRO
A23: POR QUÊ ? | K23: Protocolo de Desmame: | M23: FR | N23: 17 | O23: Relação I:E
C24: LABORATORIAIS ALTERADOS | F24: CULTURAS / SOROLOGIAS | K24: Data de prona: | M24: FIO2 | O24: Ppico | Q24: TARDE:
D25: ONTEM | E25: HOJE | F25: DATA | G25: TIPO | H25: RESULTADO | K25: Pcuff Manha | M25: PEEP | O25: Pplatô
C26: Hemoglobina | D26: 10.9 | E26: 11 | F26: 46005 | G26: SWABS | K26: Pcuff Tarde | M26: PC/VC/PS | O26: IRRS/Tobin | Q26: NOITE:
C27: Hematocrito | F27: 46005 | G27: URO | K27: Pcuff Noite | M27: Fluxo | O27: DP
C28: Leucocitos | D28: 45875 | E28: 8210 | F28: 46008 | G28: SWAB | K28: 4) ABDOMINAL /NUTRI
A29: ESCALAS | C29: plaquetas | K29: DIETA | L29: JEJUM | N29: VIA | O29: ORAL | P29: PESO: | Q29: 80 | R29: OTIMIZAR PROCINETICOS , DISCUTIR NOVA TENTATIVA DE DIETA COM CC
A30: BRADEN | B30: 13 -14 | C30: PCR | D30: 84 | E30: 67 | K30: VAZÃO ATUAL: | M30: VAZÃO META: | O30: LIQUIDA | P30: ÁGUA: | Q30: RH
A31: MORSE | B31: <41 | C31: Uréia | K31: Atingidiu meta 2000 kcal? | L31: NÃO | N31: ALMOÇO/JANTAR: SOPA COADA
A32: FUGULIN | B32: 15 -20 | C32: Creatinina | K32: Glicemia(alvo80-180mg/dl)? | L32: NÃO
A33: PPS | B33: 100 | C33: Sódio | K33: Evacuação normal? | L33: NÃO
A34: SAPS3 | B34: 38 | C34: Potássio | D34: 3.2 | K34: Profilaxia úlceras gástricas? | L34: NÃO
A35: TX.MORT% | B35: 7.5 | C35: Calcio | F35: EXAMES DE IMAGENS | K35: 5) RENAL / GENITOURINARIO
A36: DIGNO DE NOTA | C36: Magnésio | D36: 1.56 | F36: DATA | G36: TIPO | H36: RESULTADO | K36: Balanço hídrico neutro: | L36: NÃO | N36: OBS: | R36: MANTER KALEMIA >4 POR ILEO
A37: 16/10- MANTENDO CNG FECHADO LIBERADO DIETA AGUA, CHA E GELATINA/ ABERTO SNG DEVIDO DISTENSÃO ABDOMINAL- OBSERVAR,REALIZADO BANHO DE ASPERSÃO, DEAMBULOU ATÉ O WC, FICOU SENTADO NA POLTRONA. | C37: Albumina | K37: Reposição eletrolítica? | L37: SIM
C38: Troponina | K38: Diurese > 0,5 ml / Kg/H? | L38: =(J15/Q29)/E15 -> 0.26041667
C39: CPK | K39: Plano Dialítico | L39: NÃO
C40: CKMB | K40: Inicio de Dialise
...

Sheet L5
A1: FA | C1: PACIENTE | H1: IDADE | J1: ALERGIAS (anotar quando tiver) | L1: HD: | R1: LEITO
A2: DIH | C2: D.UTI | D2: 46003 | E2: PREV. ALTA | G2: QNTOS DIAS: | R2: 5
A3: HDA | R3: DATA
A4: HPP | R4: =TODAY() -> 46009
A5: MUC
A6: SUBJETIVO | C6: OBJETIVO | K6: ANALISE POR SISTEMA | R6: PLANO DO DIA
A7: QX: PACIENTE, FAMILIAR, EQUIPE ASSISTENCIAL | C7: EXAME FÍSICO ALTERADO: | K7: 1) NEURO
K8: SEDOANALGESIA | L8: VAZÃO | M8: INICIO | N8: FIM | O8: GLASGOW
O9: RASS:
O10: Pupilas:
O11: DESPERTAR DIARIO/RASS<-2
O12: - Rodizio de sedação?
O13: Avaliação dor/analgesia
A14: IMPRESSÃO GERAL | C14: CONTROLES DE ENFERMAGEM | F14: HEMODIALISE | I14: BALANÇO HIDRICO: | K14: 3) CARDIOVASCULAR
A15: (Das ultimas 24 h) | C15: CONTROLE DE (h) | F15: DATA | G15: TEMPO | H15: PERDAS | I15: DIURESE: | K15: DVAs | L15: VAZÃO | M15: INICIO | N15: FIM | O15: PAM / MMNHG
A16: BEG | B16: FALSE | D16: MIN | E16: MAX | O16: FC
A17: REG | B17: FALSE | C17: PAM: | I17: HMD: | O17: TEC
A18: MEG | B18: FALSE | C18: FC | O18: ESTAVEL HMD
A19: EVOLUÇÃO | C19: FR | I19: BH: | O19: REDUZIR DVAs
A20: FAVORÁVEL | B20: FALSE | C20: TEMP | F20: DRENOS | O20: ALTERAÇÕES ECG
A21: ESTACIONÁRIA | B21: FALSE | C21: SAT | I21: ULTIMA EVACUAÇÃO (DATA) | K21: 2) RESPIRATÓRIO
A22: DESFAVORÁVEL | B22: FALSE | C22: DEXTRO | K22: Ventilação: | M22: MODO | O22: RIMA | Q22: MANHA:
A23: POR QUÊ ? | C23: DEXTRO | K23: Protocolo de Desmame: | M23: FR | O23: Relação I:E | Q23: TOSSE
C24: LABORATORIAIS ALTERADOS | F24: CULTURAS / SOROLOGIAS | K24: Data de prona: | M24: FIO2 | O24: Ppico | Q24: TARDE:
D25: ONTEM | E25: HOJE | F25: DATA | G25: TIPO | H25: RESULTADO | K25: Pcuff Manha | M25: PEEP | O25: Pplatô
C26: Hemoglobina | K26: Pcuff Tarde | M26: PC/VC/PS | O26: IRRS/Tobin | Q26: NOITE:
C27: Hematocrito | K27: Pcuff Noite | M27: Fluxo | O27: DP
C28: Leucocitos | K28: 4) ABDOMINAL /NUTRI
A29: ESCALAS | C29: plaquetas | K29: DIETA | N29: VIA | P29: ÁGUA:
A30: BRADEN | C30: PCR | K30: VAZÃO ATUAL: | M30: VAZÃO META: | P30: PESO:
A31: MORSE | C31: Uréia | K31: Atingidiu meta 2000 kcal? | P31: ALTURA:
A32: FUGULIN | C32: Creatinina | K32: Glicemia(alvo80-180mg/dl)? | N32: OBS:
A33: PPS | C33: Sódio | K33: Evacuação normal?
A34: SAPS3 | C34: Potássio | K34: Profilaxia úlceras gástricas?
A35: TX.MORT% | C35: Calcio | F35: EXAMES DE IMAGENS | K35: 5) RENAL / GENITOURINARIO
A36: DIGNO DE NOTA | C36: Magnésio | F36: DATA | G36: TIPO | H36: RESULTADO | K36: Balanço hídrico neutro: | N36: OBS:
C37: Albumina | K37: Reposição eletrolítica?
C38: Troponina | K38: Diurese > 0,5 ml / Kg/H? | L38: =(J15/Q30)/E15 -> #DIV/0!
C39: CPK | K39: Plano Dialítico
C40: CKMB | K40: Inicio de Dialise
...

Sheet L6
A1: FA | C1: PACIENTE | H1: IDADE | J1: ALERGIAS (anotar quando tiver) | L1: HD: | R1: LEITO
A2: DIH | C2: D.UTI | D2: 46003 | E2: PREV. ALTA | G2: QNTOS DIAS: | R2: 6
A3: HDA | R3: DATA
A4: HPP | R4: =TODAY() -> 46009
A5: MUC
A6: SUBJETIVO | C6: OBJETIVO | K6: ANALISE POR SISTEMA | R6: PLANO DO DIA
A7: QX: PACIENTE, FAMILIAR, EQUIPE ASSISTENCIAL | C7: EXAME FÍSICO ALTERADO: | K7: 1) NEURO
K8: SEDOANALGESIA | L8: VAZÃO | M8: INICIO | N8: FIM | O8: GLASGOW
O9: RASS:
O10: Pupilas:
O11: DESPERTAR DIARIO/RASS<-2
O12: - Rodizio de sedação?
O13: Avaliação dor/analgesia
A14: IMPRESSÃO GERAL | C14: CONTROLES DE ENFERMAGEM | F14: HEMODIALISE | I14: BALANÇO HIDRICO: | K14: 3) CARDIOVASCULAR
A15: (Das ultimas 24 h) | C15: CONTROLE DE (h) | F15: DATA | G15: TEMPO | H15: PERDAS | I15: DIURESE: | K15: DVAs | L15: VAZÃO | M15: INICIO | N15: FIM | O15: PAM / MMNHG
A16: BEG | B16: FALSE | D16: MIN | E16: MAX | O16: FC
A17: REG | B17: FALSE | C17: PAM: | I17: HMD: | O17: TEC
A18: MEG | B18: FALSE | C18: FC | O18: ESTAVEL HMD
A19: EVOLUÇÃO | C19: FR | I19: BH: | O19: REDUZIR DVAs
A20: FAVORÁVEL | B20: FALSE | C20: TEMP | F20: DRENOS | O20: ALTERAÇÕES ECG
A21: ESTACIONÁRIA | B21: FALSE | C21: SAT | I21: ULTIMA EVACUAÇÃO (DATA) | K21: 2) RESPIRATÓRIO
A22: DESFAVORÁVEL | B22: FALSE | C22: DEXTRO | K22: Ventilação: | M22: MODO | O22: RIMA | Q22: MANHA:
A23: POR QUÊ ? | C23: DEXTRO | K23: Protocolo de Desmame: | M23: FR | O23: Relação I:E | Q23: TOSSE
C24: LABORATORIAIS ALTERADOS | F24: CULTURAS / SOROLOGIAS | K24: Data de prona: | M24: FIO2 | O24: Ppico | Q24: TARDE:
D25: ONTEM | E25: HOJE | F25: DATA | G25: TIPO | H25: RESULTADO | K25: Pcuff Manha | M25: PEEP | O25: Pplatô
C26: Hemoglobina | K26: Pcuff Tarde | M26: PC/VC/PS | O26: IRRS/Tobin | Q26: NOITE:
C27: Hematocrito | K27: Pcuff Noite | M27: Fluxo | O27: DP
C28: Leucocitos | K28: 4) ABDOMINAL /NUTRI
A29: ESCALAS | C29: plaquetas | K29: DIETA | N29: VIA | P29: ÁGUA:
A30: BRADEN | C30: PCR | K30: VAZÃO ATUAL: | M30: VAZÃO META: | P30: PESO:
A31: MORSE | C31: Uréia | K31: Atingidiu meta 2000 kcal? | P31: ALTURA:
A32: FUGULIN | C32: Creatinina | K32: Glicemia(alvo80-180mg/dl)? | N32: OBS:
A33: PPS | C33: Sódio | K33: Evacuação normal?
A34: SAPS3 | C34: Potássio | K34: Profilaxia úlceras gástricas?
A35: TX.MORT% | C35: Calcio | F35: EXAMES DE IMAGENS | K35: 5) RENAL / GENITOURINARIO
A36: DIGNO DE NOTA | C36: Magnésio | F36: DATA | G36: TIPO | H36: RESULTADO | K36: Balanço hídrico neutro: | N36: OBS:
C37: Albumina | K37: Reposição eletrolítica?
C38: Troponina | K38: Diurese > 0,5 ml / Kg/H? | L38: =(J15/Q30)/E15 -> #DIV/0!
C39: CPK | K39: Plano Dialítico
C40: CKMB | K40: Inicio de Dialise
...

Sheet L7
C1: PACIENTE | D1: APARECIDO TOLEDO | H1: IDADE | I1: 76 | J1: ALERGIAS (anotar quando tiver) | K1: NEGA | L1: HD: | M1: 1-TAQUIARRITMIA >> TAQUICARDIA VENTRICULAR SEM INSTABILIDADE HEMODINÂMICA 2- IC PERFIL B 3- ITU | R1: LEITO
A2: DIH | B2: 46006 | C2: D.UTI | D2: 46008 | E2: PREV. ALTA | G2: QNTOS DIAS: | R2: 7
A3: HDA | B3: TAQUIARRITMIA /FAAARV/ IRA / | R3: DATA
A4: HPP | B4: PACIENTE COM EPISODIOS DE DISPNEIA, DESTURAÇAO , EDEMA , INTERNADO REALIZADO MEDIDA PARA EAP, CONTROLE DE FC, E PASSAGEM DE SVD COM MELHORA CLINICA DE IRA. MANTENDO FAARV | R4: =TODAY() -> 46009
A5: MUC
A6: SUBJETIVO | C6: OBJETIVO | K6: ANALISE POR SISTEMA | R6: PLANO DO DIA
A7: QX: PACIENTE, FAMILIAR, EQUIPE ASSISTENCIAL | C7: EXAME FÍSICO ALTERADO: | K7: 1) NEURO
C8: BATIMENTO ARRITMICOS IRREGULARES ,ENCHIMENTO CAPILAR DIMINUIDO EM MEMBROS | K8: SEDOANALGESIA | L8: VAZÃO | M8: INICIO | N8: FIM | O8: GLASGOW | P8: 15
A9: SEM QUEIXAS | O9: RASS:
O10: Pupilas: | P10: PIRF
O11: DESPERTAR DIARIO/RASS<-2
O12: - Rodizio de sedação?
O13: Avaliação dor/analgesia | P13: SIM
A14: IMPRESSÃO GERAL | C14: CONTROLES DE ENFERMAGEM | F14: HEMODIALISE | I14: BALANÇO HIDRICO: | K14: 3) CARDIOVASCULAR
A15: (Das ultimas 24 h) | C15: CONTROLE DE (h) | F15: DATA | G15: TEMPO | H15: PERDAS | I15: DIURESE: | J15: 800 | K15: DVAs | L15: VAZÃO | M15: INICIO | N15: FIM | O15: PAM / MMNHG | P15: 84 | R15: FAAAR EM AMIODARONA DOSE DE IMPREGNAÇAO TERMINO HOJE , MANTER DOSE VO/ SOLICITAR ECOCARDIOGRAMA
A16: BEG | B16: FALSE | D16: MIN | E16: MAX | K16: AMIODARONA X6 | L16: 15 | M16: 46008 | O16: FC | P16: 101
A17: REG | B17: TRUE | C17: PAM: | D17: 70 | E17: 90 | I17: HMD: | O17: TEC | P17: 3
A18: MEG | B18: FALSE | C18: FC | D18: 87 | E18: 117 | O18: ESTAVEL HMD | P18: SIM
A19: EVOLUÇÃO | C19: FR | D19: 14 | E19: 18 | I19: BH: | J19: -1053 | O19: REDUZIR DVAs | P19: N/A
A20: FAVORÁVEL | B20: FALSE | C20: TEMP | D20: 35.4 | E20: 36.2 | F20: DRENOS | O20: ALTERAÇÕES ECG | P20: SIM
A21: ESTACIONÁRIA | B21: TRUE | C21: SAT | D21: ? | E21: ? | I21: ULTIMA EVACUAÇÃO (DATA) | K21: 2) RESPIRATÓRIO
A22: DESFAVORÁVEL | B22: FALSE | C22: DEXTRO | D22: 178 | E22: 334 | I22: Há 1 semana (SIC) | K22: Ventilação: | L22: AA | M22: MODO | O22: RIMA | Q22: MANHA: | R22: SpO2 = oximetro: 75% // SpO2 Gaso: 98%
A23: POR QUÊ ? | C23: DEXTRO | K23: Protocolo de Desmame: | M23: FR | N23: 13 | O23: Relação I:E
C24: LABORATORIAIS ALTERADOS | F24: CULTURAS / SOROLOGIAS | K24: Data de prona: | M24: FIO2 | O24: Ppico | Q24: TARDE:
D25: ONTEM | E25: HOJE | F25: DATA | G25: TIPO | H25: RESULTADO | K25: Pcuff Manha | M25: PEEP | O25: Pplatô
C26: Hemoglobina | F26: 46008 | G26: SWAB RETAL | K26: Pcuff Tarde | M26: PC/VC/PS | O26: IRRS/Tobin | Q26: NOITE:
C27: Hematocrito | F27: 46008 | G27: SWAB NASAL | K27: Pcuff Noite | M27: Fluxo | O27: DP
C28: Leucocitos | E28: 24 | K28: 4) ABDOMINAL /NUTRI
A29: ESCALAS | C29: plaquetas | K29: DIETA | L29: LEVE HAS/DM | N29: VIA | O29: ORAL | P29: ÁGUA: | Q29: 1500 ML | R29: AJUSTAR INSULINA//FAZER MEDIDAS LAXATIVAS//CLISTER GLICERINADO
A30: BRADEN | B30: 19 - 23 | C30: PCR | E30: 55 | K30: VAZÃO ATUAL: | M30: VAZÃO META: | P30: PESO:
A31: MORSE | B31: 41 -51 | C31: Uréia | E31: 49 | K31: Atingidiu meta 2000 kcal? | P31: ALTURA:
A32: FUGULIN | B32: 15 - 20 | C32: Creatinina | K32: Glicemia(alvo80-180mg/dl)? | L32: NÃO | N32: OBS:
A33: PPS | B33: 90 | C33: Sódio | E33: 132 | K33: Evacuação normal? | L33: NÃO
A34: SAPS3 | C34: Potássio | K34: Profilaxia úlceras gástricas? | L34: SIM
A35: TX.MORT% | C35: Calcio | E35: 7.2 | F35: EXAMES DE IMAGENS | K35: 5) RENAL / GENITOURINARIO
A36: DIGNO DE NOTA | C36: Magnésio | F36: DATA | G36: TIPO | H36: RESULTADO | K36: Balanço hídrico neutro: | L36: NÃO | N36: OBS:
A37: 17/12; PACIENTE COM DESATURAÇAO PERIFERICA NAO CONCORDANTE COM GASOMETRIA ARTERIAL | C37: Albumina | K37: Reposição eletrolítica? | L37: SIM
C38: Troponina | K38: Diurese > 0,5 ml / Kg/H? | L38: =(J15/Q30)/E15 -> #DIV/0!
C39: CPK | K39: Plano Dialítico | L39: NÃO
C40: CKMB | K40: Inicio de Dialise
...

Sheet L8
A1: 17 | B1: 577523 | C1: PACIENTE | D1: ELIZABETI GONÇALVES BRAGA | H1: IDADE | I1: 61 | J1: ALERGIAS (anotar quando tiver) | L1: HD: | M1: PO 03/12/2025 DE DESBRIDAMENTO PERIANAL + COXA ESQUERDA DEVIDO SD DE FOURNIER | R1: LEITO
A2: DIH | B2: 45994 | C2: D.UTI | D2: 46000.542 | E2: PREV. ALTA | F2: 14 | G2: QNTOS DIAS: | H2: =(D2+F2)-O2 -> 46014.542 | R2: 8
A3: HDA | B3: PACIENTE COM SÍNDROME DE FOURNIER GRAVE. RELATA INÍCIO DE FURÚNCULO, COM PIOTA HÁ DUAS SEMANAS (SIC). DIA 03/12 DESBIDAMENTO PERINEAL + COXA ESQUERDA DEVIDO SD DE FOURNIER - PROCEDIMENTO SEM INTERCORRENCIAS. ADMITIDA NA SALA VERMELHA EM VENTILAÇÃO MECÂNICA PROVENIENTE DO CC. | R3: DATA
A4: HPP | B4: A PACIENTE TEM OBESIDADE MÓRBIDA, DM E HAS. | R4: =TODAY() -> 46009
A5: MUC
A6: SUBJETIVO | C6: OBJETIVO | K6: ANALISE POR SISTEMA | R6: PLANO DO DIA
A7: QX: PACIENTE, FAMILIAR, EQUIPE ASSISTENCIAL | C7: EXAME FÍSICO ALTERADO: | K7: 1) NEURO
C8: EDEMACIADA, FERIMENTO EM REGIAO PERINEAL SECRETIVO SERO HEMATICO | K8: SEDOANALGESIA | L8: VAZÃO | M8: INICIO | N8: FIM | O8: GLASGOW | R8: JN MANTER SÓ ANALGESIA/ ENTRAR MULTIMODAL (GABAPENTINA)
A9: MANTEM SE RESPOSTA | K9: MIDAZOLAM 2X | L9: - | O9: RASS: | P9: -3
K10: FENTANIL | O10: Pupilas: | P10: PIRF
K11: PRECEDEX | L11: 4 | M11: 46005 | N11: 46008 | O11: DESPERTAR DIARIO/RASS<-2 | P11: SIM
O12: - Rodizio de sedação? | P12: N/A
O13: Avaliação dor/analgesia | P13: SIM
A14: IMPRESSÃO GERAL | C14: CONTROLES DE ENFERMAGEM | F14: HEMODIALISE | I14: BALANÇO HIDRICO: | K14: 3) CARDIOVASCULAR
A15: (Das ultimas 24 h) | C15: CONTROLE DE (h) | E15: 12 | F15: DATA | G15: TEMPO | H15: PERDAS | I15: DIURESE: | J15: 20 | K15: DVAs | L15: VAZÃO | M15: INICIO | N15: FIM | O15: PAM / MMNHG | P15: 97 | R15: NORA EM DESMAME
A16: BEG | B16: FALSE | D16: MIN | E16: MAX | F16: 46003 | G16: 3H | H16: 2000 | K16: NORADRENALINA 4X | L16: 4 | O16: FC | P16: 80
A17: REG | B17: FALSE | C17: PAM: | D17: 67 | E17: 101 | F17: 46004 | G17: 3H30 | H17: 2500 | I17: HMD: | J17: 2500 | K17: VASOPRESSINA 2X | L17: 6 ML/H | N17: 46003 | O17: TEC | P17: 3
A18: MEG | B18: TRUE | C18: FC | D18: 82 | E18: 117 | F18: 46007 | G18: 3H30 | H18: 2500 | K18: INSULINA R. | L18: 10 ML/H | M18: 46007 | N18: 46008 | O18: ESTAVEL HMD | P18: NÃO
A19: EVOLUÇÃO | C19: FR | D19: 16 | E19: 19 | F19: 46008 | G19: 3H30MIN | H19: 2500 | I19: BH: | J19: -778 | O19: REDUZIR DVAs | P19: SIM
A20: FAVORÁVEL | B20: TRUE | C20: TEMP | D20: 36 | E20: 37.3 | F20: DRENOS | O20: ALTERAÇÕES ECG | P20: NÃO
A21: ESTACIONÁRIA | B21: FALSE | C21: SAT | D21: 94 | E21: 98 | I21: ULTIMA EVACUAÇÃO (DATA) | K21: 2) RESPIRATÓRIO
A22: DESFAVORÁVEL | B22: FALSE | C22: DEXTRO | D22: 136 | E22: 241 | I22: 17/12 +++ | K22: Ventilação: | L22: TOT | M22: MODO | N22: PSV | O22: RIMA | P22: 23 | Q22: MANHA: | R22: TENTATIVA DE EXTUBAÇAO ATE 21/12 ASSINAR TERMO TQT
A23: POR QUÊ ? | K23: Protocolo de Desmame: | M23: FR | N23: 17 | O23: Relação I:E
A24: DEPENDIENTE DE DVAS DESPERTAR INEFICAZ | C24: LABORATORIAIS ALTERADOS | F24: CULTURAS / SOROLOGIAS | K24: Data de prona: | M24: FIO2 | N24: 21 | O24: Ppico | Q24: TARDE:
D25: ONTEM | E25: HOJE | F25: DATA | G25: TIPO | H25: RESULTADO | K25: Pcuff Manha | L25: 30 | M25: PEEP | N25: 5 | O25: Pplatô
C26: Hemoglobina | D26: 6.7 | E26: 7.5 | K26: Pcuff Tarde | L26: 30 | M26: PC/VC/PS | N26: 8 | O26: IRRS/Tobin | Q26: NOITE:
C27: Hematocrito | D27: 21 | E27: 21 | K27: Pcuff Noite | L27: 30 | M27: Fluxo | O27: DP | Q27: ps 8. secretiva
C28: Leucocitos | D28: 22 | E28: 18350 | K28: 4) ABDOMINAL /NUTRI
A29: ESCALAS | C29: plaquetas | K29: DIETA | L29: DIBEN | N29: VIA | O29: SNE | P29: PESO: | Q29: 131 | R29: OTIMIZO NPH
A30: BRADEN | B30: 10 A 12 | C30: PCR | D30: 48 | E30: 60 | K30: VAZÃO ATUAL: | L30: 58 | M30: VAZÃO META: | O30: 75 ML/H | P30: ÁGUA: | Q30: RH
A31: MORSE | B31: 41 - 51 | C31: Uréia | D31: 117 | E31: 168 | K31: Atingidiu meta 2000 kcal? | L31: NÃO | N31: OBS: LIBERADO DIETA. SUPLEMENTAÇÃO HIPERPROTEICA
A32: FUGULIN | B32: > 31 | C32: Creatinina | D32: 4.5 | E32: 4.8 | K32: Glicemia(alvo80-180mg/dl)? | L32: NÃO
A33: PPS | B33: 70 | C33: Sódio | K33: Evacuação normal? | L33: SIM
A34: SAPS3 | B34: 80 | C34: Potássio | D34: 3.3 | E34: 3.2 | K34: Profilaxia úlceras gástricas? | L34: SIM
A35: TX.MORT% | B35: 85.8 | C35: Calcio | D35: 7 | F35: EXAMES DE IMAGENS | K35: 5) RENAL / GENITOURINARIO
A36: DIGNO DE NOTA | C36: Magnésio | F36: DATA | G36: TIPO | H36: RESULTADO | K36: Balanço hídrico neutro: | L36: SIM | N36: OBS: | R36: CORREÇÃO DE CALCIO E POTASSIO
A37: 10/12PACIENTE APRESENTA GRANDE QUANTIDADE DE SANGRAMENTO EM FOURNIER, III | C37: Albumina | D37: 2.2 | F37: 09 E 13/12 | G37: RX | H37: SNE LOCADA | K37: Reposição eletrolítica? | L37: SIM
C38: Troponina | F38: 46005 | G38: RX | K38: Diurese > 0,5 ml / Kg/H? | L38: =(J15/Q29)/E15 -> 0.012722646
C39: CPK | K39: Plano Dialítico | L39: SIM
C40: CKMB | K40: Inicio de Dialise
...

Sheet L9
A1: FA | B1: 579000 | C1: PACIENTE | D1: ANTONIO CARLOS CASSIMIRA | H1: IDADE | I1: 58 | J1: ALERGIAS (anotar quando tiver) | L1: HD: | M1: 1- PCR REVERTIDA 2- SCA ? 3- FAAR | R1: LEITO
A2: DIH | B2: 46007 | C2: D.UTI | D2: 16/12 AS | E2: PREV. ALTA | G2: QNTOS DIAS: | R2: LEITO 09
A3: HDA | B3: PACIENTE ADMITIDO NA UNIDADE EM PCR APÓS MAL SÚBITO OCORRIDO DURANTE ATIVIDADE LABORAL. REALIZADOS 4 CICLOS DE RCP CONFORME PROTOCOLO ACLS. ECG PÓS-ROSC EVIDENCIOU ALTERAÇÕES DE REPOLARIZAÇÃO VENTRICULAR, COM RITMO DE FAAR, INFRADESNIVELAMENTO DO SEGMENTO ST EM DII E V1, E SUPRADESNIVELAMENTO DO ST EM V3 E V4. CASO DISCUTIDO COM DR. YANCO QUANTO À POSSIBILIDADE DE TROMBÓLISE, SENDO CONTRAINDICADA NO MOMENTO.*TROMBÓLISE NÃO LIBERADA PELO MÉDICO CARDIOLOGISTA* | R3: DATA
A4: HPP | B4: SEM RELATO | R4: =TODAY() -> 46009
A5: MUC | B5: SEM RELATO
A6: SUBJETIVO | C6: OBJETIVO | K6: ANALISE POR SISTEMA | R6: PLANO DO DIA
A7: QX: PACIENTE, FAMILIAR, EQUIPE ASSISTENCIAL | C7: EXAME FÍSICO ALTERADO: | K7: 1) NEURO
K8: SEDOANALGESIA | L8: VAZÃO | M8: INICIO | N8: FIM | O8: GLASGOW | R8: JANELA NEUROLOGICA
K9: MIDAZOLAM 2X | L9: 5 | M9: 46007 | N9: 46008 | O9: RASS: | P9: -5
K10: FENTANIL | L10: 2 | M10: 46007 | N10: 46008 | O10: Pupilas:
K11: ROCURONIO | L11: 0 | M11: 46007 | N11: 46008 | O11: DESPERTAR DIARIO/RASS<-2 | P11: SIM
K12: PRECEDEX X2 | L12: 10 | M12: 46008 | O12: - Rodizio de sedação? | P12: NÃO
O13: Avaliação dor/analgesia | P13: SIM
A14: IMPRESSÃO GERAL | C14: CONTROLES DE ENFERMAGEM | F14: HEMODIALISE | I14: BALANÇO HIDRICO: | K14: 3) CARDIOVASCULAR
A15: (Das ultimas 24 h) | C15: CONTROLE DE (h) | E15: 24 | F15: DATA | G15: TEMPO | H15: PERDAS | I15: DIURESE: | J15: 550 | K15: DVAs | L15: VAZÃO | M15: INICIO | N15: FIM | O15: PAM / MMNHG | P15: 100 | R15: CURVA DE TROPONINA
A16: BEG | B16: FALSE | D16: MIN | E16: MAX | K16: NORADRENALINA 4X | L16: 15ML/H | M16: 46007 | N16: 46007 | O16: FC | P16: 92
A17: REG | B17: FALSE | C17: PAM: | D17: 55 | E17: 100 | I17: HMD: | O17: TEC | P17: <2
A18: MEG | B18: TRUE | C18: FC | D18: 79 | E18: 94 | O18: ESTAVEL HMD | P18: SIM
A19: EVOLUÇÃO | C19: FR | D19: 13 | E19: 22 | I19: BH: | J19: =1346 -> 1346 | O19: REDUZIR DVAs | P19: SIM
A20: FAVORÁVEL | B20: FALSE | C20: TEMP | D20: 35.6 | E20: 37.8 | F20: DRENOS | O20: ALTERAÇÕES ECG | P20: NÃO
A21: ESTACIONÁRIA | B21: TRUE | C21: SAT | D21: 94 | E21: 100 | I21: ULTIMA EVACUAÇÃO (DATA) | K21: 2) RESPIRATÓRIO
A22: DESFAVORÁVEL | B22: FALSE | C22: DEXTRO | D22: 97 | E22: 140 | I22: -- | K22: Ventilação: | L22: TOT | M22: MODO | N22: PSV | O22: RIMA | P22: 23 | Q22: MANHA: | R22: noite: periodos de agitação, sem nc
A23: POR QUÊ ? | K23: Protocolo de Desmame: | M23: FR | N23: 14 | O23: Relação I:E
A24: MANTEM SEDAÇAO HIPTENSO | C24: LABORATORIAIS ALTERADOS | F24: CULTURAS / SOROLOGIAS | K24: Data de prona: | M24: FIO2 | N24: 21 | O24: Ppico | Q24: TARDE:
D25: ONTEM | E25: HOJE | F25: DATA | G25: TIPO | H25: RESULTADO | K25: Pcuff Manha | M25: PEEP | N25: 6 | O25: Pplatô
C26: Hemoglobina | E26: 12 | F26: 46007 | G26: SWAB | K26: Pcuff Tarde | M26: PC/VC/PS | N26: 7 | O26: IRRS/Tobin | Q26: NOITE:
C27: Hematocrito | F27: 46007 | G27: HEMO | K27: Pcuff Noite | L27: 30 | M27: Fluxo | O27: DP
C28: Leucocitos | D28: 19510 | E28: 13660 | F28: 46007 | G28: URO | K28: 4) ABDOMINAL /NUTRI
A29: ESCALAS | C29: plaquetas | F29: 46007 | G29: ST | K29: DIETA | L29: HP ENERGI | N29: VIA | O29: SNE | P29: PESO: | Q29: 81.7 | R29: INICIAR DIETA
A30: BRADEN | B30: 10 --12 | C30: PCR | D30: 45 | E30: 65 | K30: VAZÃO ATUAL: | L30: 0 | M30: VAZÃO META: | O30: 55ML/H | P30: ÁGUA: | Q30: RH
A31: MORSE | B31: 41 51 | C31: Uréia | K31: Atingidiu meta 2000 kcal? | L31: NÃO | N31: OBS: 1,73 ALTURA
A32: FUGULIN | B32: > 31 | C32: Creatinina | K32: Glicemia(alvo80-180mg/dl)? | L32: SIM
A33: PPS | B33: 100 | C33: Sódio | K33: Evacuação normal? | L33: NÃO
A34: SAPS3 | C34: Potássio | E34: 3.5 | K34: Profilaxia úlceras gástricas? | L34: SIM
A35: TX.MORT% | C35: Calcio | F35: EXAMES DE IMAGENS | K35: 5) RENAL / GENITOURINARIO
A36: DIGNO DE NOTA | C36: Magnésio | F36: DATA | G36: TIPO | H36: RESULTADO | K36: Balanço hídrico neutro: | L36: SIM | N36: OBS:
A37: DESLIGADO MIDAZOLAM + FENTANIL INICIADO COM PRECEDEX PACIENTE BASTANTE AGITADO INICIADO INICADO COM MEDIADAS PARA DESPERTA PATOLOGICO,INSERIDO NA CROSS PARA CAT.+ AVALIAÇÃO DA CARDILOGIA. OBS: FALTA ENCAMINHAR PEDIDO DE ECOCARDIOGRAMA | C37: Albumina | F37: 46007 | G37: TC CRANIO | H37: https://mobilemed-prod.s3.amazonaws.com/producao/exame/laudo_signed/1765932638107-hkkFNA3O_AzHBZYofSNvjY~pjHSqwQ.pdf | K37: Reposição eletrolítica? | L37: NÃO
C38: Troponina | D38: 1.16 | F38: 46007 | G38: TC TORAX | H38: https://mobilemed-prod.s3.amazonaws.com/producao/exame/laudo_signed/1765931589896-IrZmAJN7sdxNyEMhml8BR5YLW5q0mr.pdf | K38: Diurese > 0,5 ml / Kg/H? | L38: =(J15/Q29)/E15 -> 0.28049776
C39: CPK | D39: 531 | E39: 324 | K39: Plano Dialítico | L39: NÃO
C40: CKMB | D40: 39 | K40: Inicio de Dialise
...

Sheet L10
A1: FA | B1: 46032 | C1: PACIENTE | D1: VANESSA APARECIDA RODRIGUES DOS SANTOS | H1: IDADE | I1: 36 | J1: ALERGIAS (anotar quando tiver) | K1: BENZETACIL | L1: HD: | M1: 1-CHOQUE SEPTICO >> PNEUMONIA >> TUBERCULOSE PULMONAR 2-DERRAME PLEURAL 3-PEDICULOSE 4-POS PCR 1 CICLO | R1: LEITO
A2: DIH | B2: 46007 | C2: D.UTI | D2: 46007 | E2: PREV. ALTA | G2: QNTOS DIAS: | R2: 10
A3: HDA | B3: PACIENTE ADMITIDA NA UPA ROSOLEM E, 10/12 COM TOSSE PRODUTIVA DISPNEIA E QUEDA DE ESTADO GERAL , INCIADO TRATAMENTO POR PNEUMONIA E INVESTIGAÇAO DE TB, EVOLUI COM PIORA CLINICA EM 12/12/25 HIPOXIA E PARADA CARDIACA REVERTIDA EM 1 CICLO, PRECISANDO DE IOT E DVAS. | R3: DATA
A4: HPP | B4: ETILISMO, YABAGISMO, DEPENDENCIA QUIMICA (CRACK)/ | R4: =TODAY() -> 46009
A5: MUC | B5: SEM INFORMAÇÃO
A6: SUBJETIVO | C6: OBJETIVO | K6: ANALISE POR SISTEMA | R6: PLANO DO DIA
A7: QX: PACIENTE, FAMILIAR, EQUIPE ASSISTENCIAL | C7: EXAME FÍSICO ALTERADO: | K7: 1) NEURO
K8: SEDOANALGESIA | L8: VAZÃO | M8: INICIO | N8: FIM | O8: GLASGOW | R8: MANTER SEDAÇAO E BLOQUEO 24 H
A9: PACIENTE GRAVE INSTAVEL | K9: MIDAZOLAM 2X | L9: 15 | O9: RASS: | P9: -5
K10: FENTANIL X2: | L10: 10 | O10: Pupilas: | P10: PIRF
K11: ROCURONIO | L11: 15 ML/H | O11: DESPERTAR DIARIO/RASS<-2 | P11: NÃO
O12: - Rodizio de sedação? | P12: NÃO
O13: Avaliação dor/analgesia | P13: SIM
A14: IMPRESSÃO GERAL | C14: CONTROLES DE ENFERMAGEM | F14: HEMODIALISE | I14: BALANÇO HIDRICO: | K14: 3) CARDIOVASCULAR
A15: (Das ultimas 24 h) | C15: (SÓ DADOS ALTERADOS) | F15: DATA | G15: TEMPO | H15: PERDAS | I15: DIURESE: | J15: 400 | K15: DVAs | L15: VAZÃO | M15: INICIO | N15: FIM | O15: PAM / MMNHG | P15: 90 | R15: TENTAR DESMAME DVAS
A16: BEG | B16: FALSE | D16: MIN | E16: MAX | K16: NORADRENALINA 8X | L16: 22 | O16: FC | P16: 124
A17: REG | B17: FALSE | C17: PAM: | D17: 80 | E17: 98 | I17: HMD: | K17: VASOPRESSINA 2X | L17: 6 | O17: TEC | P17: 4
A18: MEG | B18: TRUE | C18: FC | D18: 131 | E18: 142 | O18: ESTAVEL HMD | P18: NÃO
A19: EVOLUÇÃO | C19: FR | D19: 28 | E19: 28 | I19: BH: | O19: REDUZIR DVAs | P19: NÃO
A20: FAVORÁVEL | B20: FALSE | C20: TEMP | D20: 35 | E20: 35.5 | F20: DRENOS | O20: ALTERAÇÕES ECG | P20: NÃO
A21: ESTACIONÁRIA | B21: FALSE | C21: SAT | D21: 91 | E21: 100 | I21: ULTIMA EVACUAÇÃO (DATA) | K21: 2) RESPIRATÓRIO
A22: DESFAVORÁVEL | B22: TRUE | C22: DEXTRO | D22: 52 | E22: 133 | K22: Ventilação: | L22: TOT | M22: MODO | N22: VCV | O22: RIMA | P22: 23 | Q22: MANHA: | R22: NOVO CONTROLE RX 07;00H PNEUMOTORAX TRABECULADO ??GASO
A23: POR QUÊ ? | K23: Protocolo de Desmame: | M23: FR | N23: 28 | O23: Relação I:E
A24: DEPENDIENTE DE DVAS E VM PARAMETROS ALTS | C24: LABORATORIAIS ALTERADOS | F24: CULTURAS / SOROLOGIAS | K24: Data de prona: | M24: FIO2 | N24: 70 | O24: Ppico | P24: 47 | Q24: TARDE:
D25: ONTEM | E25: HOJE | F25: DATA | G25: TIPO | H25: RESULTADO | K25: Pcuff Manha | M25: PEEP | N25: 6 | O25: Pplatô | P25: 37
C26: Hemoglobina | D26: 5.6 | E26: 9 | F26: 46008 | G26: SWAB | K26: Pcuff Tarde | M26: PC/VC/PS | N26: 330 | O26: IRRS/Tobin | Q26: NOITE:
C27: Hematocrito | D27: 19 | E27: 32 | F27: 46008 | G27: HEMO | K27: Pcuff Noite | L27: 40 | M27: Fluxo | O27: DP | P27: 30 | Q27: Retiro flextube.
C28: Leucocitos | D28: 16710 | E28: 7190 | F28: 46008 | G28: URO | K28: 4) ABDOMINAL /NUTRI
A29: ESCALAS | C29: plaquetas | E29: 91 | F29: 46008 | G29: SECREÇÃO | K29: DIETA | L29: JEJUM | N29: VIA | P29: PESO: | Q29: 60
A30: BRADEN | B30: 10 - 12 | C30: PCR | D30: 69 | E30: 67 | K30: VAZÃO ATUAL: | L30: *** | M30: VAZÃO META: | O30: *** | P30: ÁGUA: | Q30: RH
A31: MORSE | B31: 41 - 51 | C31: Uréia | D31: 120 | E31: 114 | K31: Atingidiu meta 2000 kcal? | L31: NÃO | N31: OBS: 1,62 ALTURA
A32: FUGULIN | B32: >41 | C32: Creatinina | D32: 2.2 | E32: 2.2 | K32: Glicemia(alvo80-180mg/dl)? | L32: NÃO
A33: PPS | B33: 90 | C33: Sódio | D33: 150 | E33: 151 | K33: Evacuação normal? | L33: NÃO
A34: SAPS3 | C34: Potássio | D34: 6.6 | K34: Profilaxia úlceras gástricas? | L34: SIM
A35: TX.MORT% | C35: Calcio | D35: 7.8 | F35: EXAMES DE IMAGENS | K35: 5) RENAL / GENITOURINARIO
A36: DIGNO DE NOTA | C36: Magnésio | D36: 1.38 | E36: 1.38 | F36: DATA | G36: TIPO | H36: RESULTADO | K36: Balanço hídrico neutro: | L36: SIM | N36: OBS: | R36: REPOR CALCIO/ MEDIDA PARA HIPERCALEMIA
A37: 17/12 RECEBEU 1 CH / TROCA DE CVD POR OBSTRUÇÃO / TROCA DE CNE POR NÃO ALOCAÇÃO | C37: Albumina | F37: 46007 | G37: TC | H37: https://mobilemed-prod.s3.amazonaws.com/producao/exame/laudo_signed/1765935468548-aKdDp6iT9z6wp8oWl54XdX6JS6Xyd~.pdf | K37: Reposição eletrolítica? | L37: SIM
C38: Troponina | F38: 46008 | G38: RX TORAX | H38: pneumotorax trabeculado? | K38: Diurese > 0,5 ml / Kg/H?
C39: CPK | K39: Plano Dialítico | L39: NÃO
C40: CKMB | K40: Inicio de Dialise
...

Sheet MODELO BASE
A1: FA | C1: PACIENTE | H1: IDADE | J1: ALERGIAS (anotar quando tiver) | L1: HD: | R1: LEITO
A2: DIH | C2: D.UTI | D2: 46003 | E2: PREV. ALTA | G2: QNTOS DIAS:
A3: HDA | R3: DATA
A4: HPP | R4: =TODAY() -> 46009
A5: MUC
A6: SUBJETIVO | C6: OBJETIVO | K6: ANALISE POR SISTEMA | R6: PLANO DO DIA
A7: QX: PACIENTE, FAMILIAR, EQUIPE ASSISTENCIAL | C7: EXAME FÍSICO ALTERADO: | K7: 1) NEURO
K8: SEDOANALGESIA | L8: VAZÃO | M8: INICIO | N8: FIM | O8: GLASGOW
O9: RASS:
O10: Pupilas:
O11: DESPERTAR DIARIO/RASS<-2
O12: - Rodizio de sedação?
O13: Avaliação dor/analgesia
A14: IMPRESSÃO GERAL | C14: CONTROLES DE ENFERMAGEM | F14: HEMODIALISE | I14: BALANÇO HIDRICO: | K14: 3) CARDIOVASCULAR
A15: (Das ultimas 24 h) | C15: CONTROLE DE (h) | F15: DATA | G15: TEMPO | H15: PERDAS | I15: DIURESE: | K15: DVAs | L15: VAZÃO | M15: INICIO | N15: FIM | O15: PAM / MMNHG
A16: BEG | B16: FALSE | D16: MIN | E16: MAX | O16: FC
A17: REG | B17: FALSE | C17: PAM: | I17: HMD: | O17: TEC
A18: MEG | B18: FALSE | C18: FC | O18: ESTAVEL HMD
A19: EVOLUÇÃO | C19: FR | I19: BH: | O19: REDUZIR DVAs
A20: FAVORÁVEL | B20: FALSE | C20: TEMP | F20: DRENOS | O20: ALTERAÇÕES ECG
A21: ESTACIONÁRIA | B21: FALSE | C21: SAT | I21: ULTIMA EVACUAÇÃO (DATA) | K21: 2) RESPIRATÓRIO
A22: DESFAVORÁVEL | B22: FALSE | C22: DEXTRO | K22: Ventilação: | M22: MODO | O22: RIMA | Q22: MANHA:
A23: POR QUÊ ? | C23: DEXTRO | K23: Protocolo de Desmame: | M23: FR | O23: Relação I:E | Q23: TOSSE
C24: LABORATORIAIS ALTERADOS | F24: CULTURAS / SOROLOGIAS | K24: Data de prona: | M24: FIO2 | O24: Ppico | Q24: TARDE:
D25: ONTEM | E25: HOJE | F25: DATA | G25: TIPO | H25: RESULTADO | K25: Pcuff Manha | M25: PEEP | O25: Pplatô
C26: Hemoglobina | K26: Pcuff Tarde | M26: PC/VC/PS | O26: IRRS/Tobin | Q26: NOITE:
C27: Hematocrito | K27: Pcuff Noite | M27: Fluxo | O27: DP
C28: Leucocitos | K28: 4) ABDOMINAL /NUTRI
A29: ESCALAS | C29: plaquetas | K29: DIETA | N29: VIA | P29: ÁGUA:
A30: BRADEN | C30: PCR | K30: VAZÃO ATUAL: | M30: VAZÃO META: | P30: PESO:
A31: MORSE | C31: Uréia | K31: Atingidiu meta 2000 kcal? | P31: ALTURA:
A32: FUGULIN | C32: Creatinina | K32: Glicemia(alvo80-180mg/dl)? | N32: OBS:
A33: PPS | C33: Sódio | K33: Evacuação normal?
A34: SAPS3 | C34: Potássio | K34: Profilaxia úlceras gástricas?
A35: TX.MORT% | C35: Calcio | F35: EXAMES DE IMAGENS | K35: 5) RENAL / GENITOURINARIO
A36: DIGNO DE NOTA | C36: Magnésio | F36: DATA | G36: TIPO | H36: RESULTADO | K36: Balanço hídrico neutro: | N36: OBS:
C37: Albumina | K37: Reposição eletrolítica?
C38: Troponina | K38: Diurese > 0,5 ml / Kg/H? | L38: =(J15/Q30)/E15 -> #DIV/0!
C39: CPK | K39: Plano Dialítico
C40: CKMB | K40: Inicio de Dialise
...
